<?xml version="1.0"?>
<robot name="my_robot" xmlns:xacro="http://ros.org/wiki/xacro">

  <!-- Base link -->
  <link name="base_link">
    <visual>
      <geometry>
        <box size="0.4 0.3 0.1"/> <!-- جسم الروبوت -->
      </geometry>
      <origin xyz="0 0 0" rpy="0 0 0"/>
      <material name="blue"/>
    </visual>
    <collision>
      <geometry>
        <box size="0.4 0.3 0.1"/>
      </geometry>
    </collision>
    <inertial>
      <mass value="5"/>
      <inertia ixx="0.1" iyy="0.1" izz="0.1" ixy="0" ixz="0" iyz="0"/>
    </inertial>
  </link>

  <!-- Four Wheels -->
  <xacro:macro name="wheel" params="name x y">
    <link name="${name}_wheel">
      <visual>
        <geometry>
          <cylinder radius="0.05" length="0.02"/>
        </geometry>
        <origin xyz="0 0 0" rpy="1.57 0 0"/>
        <material name="black"/>
      </visual>
      <collision>
        <geometry>
          <cylinder radius="0.05" length="0.02"/>
        </geometry>
      </collision>
      <inertial>
        <mass value="1"/>
        <inertia ixx="0.01" iyy="0.01" izz="0.01" ixy="0" ixz="0" iyz="0"/>
      </inertial>
    </link>

    <joint name="${name}_joint" type="continuous">
      <parent link="base_link"/>
      <child link="${name}_wheel"/>
      <origin xyz="${x} ${y} -0.05" rpy="0 0 0"/>
      <axis xyz="0 1 0"/>
    </joint>
  </xacro:macro>

  <!-- Instantiate wheels -->
  <xacro:wheel name="front_left"  x="0.15" y="0.15"/>
  <xacro:wheel name="front_right" x="0.15" y="-0.15"/>
  <xacro:wheel name="rear_left"   x="-0.15" y="0.15"/>
  <xacro:wheel name="rear_right"  x="-0.15" y="-0.15"/>

  <!-- LiDAR -->
  <link name="lidar">
    <visual>
      <geometry>
        <cylinder radius="0.05" length="0.1"/>
      </geometry>
      <origin xyz="0 0 0.1" rpy="0 0 0"/>
      <material name="red"/>
    </visual>
  </link>

  <joint name="lidar_joint" type="fixed">
    <parent link="base_link"/>
    <child link="lidar"/>
    <origin xyz="0 0 0.15" rpy="0 0 0"/>
  </joint>

</robot>

